{
 "cells": [
  {
   "cell_type": "code",
   "execution_count": null,
   "metadata": {},
   "outputs": [],
   "source": [
    "import telegram\n",
    "from telegram import Update\n",
    "from telegram.ext import Updater, CommandHandler, MessageHandler, Filters, CallbackContext, ConversationHandler\n",
    "import configparser\n",
    "import logging\n",
    "import firebase_admin\n",
    "from firebase_admin import credentials, firestore\n",
    "from ChatGPT_HKBU import HKBU_ChatGPT\n",
    "from firebase_admin import credentials\n"
   ]
  },
  {
   "cell_type": "code",
   "execution_count": null,
   "metadata": {},
   "outputs": [
    {
     "name": "stderr",
     "output_type": "stream",
     "text": [
      "ERROR:grpc._plugin_wrapping:AuthMetadataPluginCallback \"<google.auth.transport.grpc.AuthMetadataPlugin object at 0x1064fee00>\" raised exception!\n",
      "Traceback (most recent call last):\n",
      "  File \"/Users/liting/Desktop/7940_GroupProject/.venv/lib/python3.10/site-packages/grpc/_plugin_wrapping.py\", line 105, in __call__\n",
      "    self._metadata_plugin(\n",
      "  File \"/Users/liting/Desktop/7940_GroupProject/.venv/lib/python3.10/site-packages/google/auth/transport/grpc.py\", line 95, in __call__\n",
      "    callback(self._get_authorization_headers(context), None)\n",
      "  File \"/Users/liting/Desktop/7940_GroupProject/.venv/lib/python3.10/site-packages/google/auth/transport/grpc.py\", line 81, in _get_authorization_headers\n",
      "    self._credentials.before_request(\n",
      "  File \"/Users/liting/Desktop/7940_GroupProject/.venv/lib/python3.10/site-packages/google/auth/credentials.py\", line 239, in before_request\n",
      "    self._blocking_refresh(request)\n",
      "  File \"/Users/liting/Desktop/7940_GroupProject/.venv/lib/python3.10/site-packages/google/auth/credentials.py\", line 202, in _blocking_refresh\n",
      "    self.refresh(request)\n",
      "  File \"/Users/liting/Desktop/7940_GroupProject/.venv/lib/python3.10/site-packages/google/oauth2/service_account.py\", line 448, in refresh\n",
      "    access_token, expiry, _ = _client.jwt_grant(\n",
      "  File \"/Users/liting/Desktop/7940_GroupProject/.venv/lib/python3.10/site-packages/google/oauth2/_client.py\", line 299, in jwt_grant\n",
      "    response_data = _token_endpoint_request(\n",
      "  File \"/Users/liting/Desktop/7940_GroupProject/.venv/lib/python3.10/site-packages/google/oauth2/_client.py\", line 270, in _token_endpoint_request\n",
      "    _handle_error_response(response_data, retryable_error)\n",
      "  File \"/Users/liting/Desktop/7940_GroupProject/.venv/lib/python3.10/site-packages/google/oauth2/_client.py\", line 69, in _handle_error_response\n",
      "    raise exceptions.RefreshError(\n",
      "google.auth.exceptions.RefreshError: ('invalid_grant: Invalid JWT Signature.', {'error': 'invalid_grant', 'error_description': 'Invalid JWT Signature.'})\n",
      "ERROR:grpc._plugin_wrapping:AuthMetadataPluginCallback \"<google.auth.transport.grpc.AuthMetadataPlugin object at 0x1064fee00>\" raised exception!\n",
      "Traceback (most recent call last):\n",
      "  File \"/Users/liting/Desktop/7940_GroupProject/.venv/lib/python3.10/site-packages/grpc/_plugin_wrapping.py\", line 105, in __call__\n",
      "    self._metadata_plugin(\n",
      "  File \"/Users/liting/Desktop/7940_GroupProject/.venv/lib/python3.10/site-packages/google/auth/transport/grpc.py\", line 95, in __call__\n",
      "    callback(self._get_authorization_headers(context), None)\n",
      "  File \"/Users/liting/Desktop/7940_GroupProject/.venv/lib/python3.10/site-packages/google/auth/transport/grpc.py\", line 81, in _get_authorization_headers\n",
      "    self._credentials.before_request(\n",
      "  File \"/Users/liting/Desktop/7940_GroupProject/.venv/lib/python3.10/site-packages/google/auth/credentials.py\", line 239, in before_request\n",
      "    self._blocking_refresh(request)\n",
      "  File \"/Users/liting/Desktop/7940_GroupProject/.venv/lib/python3.10/site-packages/google/auth/credentials.py\", line 202, in _blocking_refresh\n",
      "    self.refresh(request)\n",
      "  File \"/Users/liting/Desktop/7940_GroupProject/.venv/lib/python3.10/site-packages/google/oauth2/service_account.py\", line 448, in refresh\n",
      "    access_token, expiry, _ = _client.jwt_grant(\n",
      "  File \"/Users/liting/Desktop/7940_GroupProject/.venv/lib/python3.10/site-packages/google/oauth2/_client.py\", line 299, in jwt_grant\n",
      "    response_data = _token_endpoint_request(\n",
      "  File \"/Users/liting/Desktop/7940_GroupProject/.venv/lib/python3.10/site-packages/google/oauth2/_client.py\", line 270, in _token_endpoint_request\n",
      "    _handle_error_response(response_data, retryable_error)\n",
      "  File \"/Users/liting/Desktop/7940_GroupProject/.venv/lib/python3.10/site-packages/google/oauth2/_client.py\", line 69, in _handle_error_response\n",
      "    raise exceptions.RefreshError(\n",
      "google.auth.exceptions.RefreshError: ('invalid_grant: Invalid JWT Signature.', {'error': 'invalid_grant', 'error_description': 'Invalid JWT Signature.'})\n",
      "ERROR:grpc._plugin_wrapping:AuthMetadataPluginCallback \"<google.auth.transport.grpc.AuthMetadataPlugin object at 0x1064fee00>\" raised exception!\n",
      "Traceback (most recent call last):\n",
      "  File \"/Users/liting/Desktop/7940_GroupProject/.venv/lib/python3.10/site-packages/grpc/_plugin_wrapping.py\", line 105, in __call__\n",
      "    self._metadata_plugin(\n",
      "  File \"/Users/liting/Desktop/7940_GroupProject/.venv/lib/python3.10/site-packages/google/auth/transport/grpc.py\", line 95, in __call__\n",
      "    callback(self._get_authorization_headers(context), None)\n",
      "  File \"/Users/liting/Desktop/7940_GroupProject/.venv/lib/python3.10/site-packages/google/auth/transport/grpc.py\", line 81, in _get_authorization_headers\n",
      "    self._credentials.before_request(\n",
      "  File \"/Users/liting/Desktop/7940_GroupProject/.venv/lib/python3.10/site-packages/google/auth/credentials.py\", line 239, in before_request\n",
      "    self._blocking_refresh(request)\n",
      "  File \"/Users/liting/Desktop/7940_GroupProject/.venv/lib/python3.10/site-packages/google/auth/credentials.py\", line 202, in _blocking_refresh\n",
      "    self.refresh(request)\n",
      "  File \"/Users/liting/Desktop/7940_GroupProject/.venv/lib/python3.10/site-packages/google/oauth2/service_account.py\", line 448, in refresh\n",
      "    access_token, expiry, _ = _client.jwt_grant(\n",
      "  File \"/Users/liting/Desktop/7940_GroupProject/.venv/lib/python3.10/site-packages/google/oauth2/_client.py\", line 299, in jwt_grant\n",
      "    response_data = _token_endpoint_request(\n",
      "  File \"/Users/liting/Desktop/7940_GroupProject/.venv/lib/python3.10/site-packages/google/oauth2/_client.py\", line 270, in _token_endpoint_request\n",
      "    _handle_error_response(response_data, retryable_error)\n",
      "  File \"/Users/liting/Desktop/7940_GroupProject/.venv/lib/python3.10/site-packages/google/oauth2/_client.py\", line 69, in _handle_error_response\n",
      "    raise exceptions.RefreshError(\n",
      "google.auth.exceptions.RefreshError: ('invalid_grant: Invalid JWT Signature.', {'error': 'invalid_grant', 'error_description': 'Invalid JWT Signature.'})\n",
      "ERROR:grpc._plugin_wrapping:AuthMetadataPluginCallback \"<google.auth.transport.grpc.AuthMetadataPlugin object at 0x1064fee00>\" raised exception!\n",
      "Traceback (most recent call last):\n",
      "  File \"/Users/liting/Desktop/7940_GroupProject/.venv/lib/python3.10/site-packages/grpc/_plugin_wrapping.py\", line 105, in __call__\n",
      "    self._metadata_plugin(\n",
      "  File \"/Users/liting/Desktop/7940_GroupProject/.venv/lib/python3.10/site-packages/google/auth/transport/grpc.py\", line 95, in __call__\n",
      "    callback(self._get_authorization_headers(context), None)\n",
      "  File \"/Users/liting/Desktop/7940_GroupProject/.venv/lib/python3.10/site-packages/google/auth/transport/grpc.py\", line 81, in _get_authorization_headers\n",
      "    self._credentials.before_request(\n",
      "  File \"/Users/liting/Desktop/7940_GroupProject/.venv/lib/python3.10/site-packages/google/auth/credentials.py\", line 239, in before_request\n",
      "    self._blocking_refresh(request)\n",
      "  File \"/Users/liting/Desktop/7940_GroupProject/.venv/lib/python3.10/site-packages/google/auth/credentials.py\", line 202, in _blocking_refresh\n",
      "    self.refresh(request)\n",
      "  File \"/Users/liting/Desktop/7940_GroupProject/.venv/lib/python3.10/site-packages/google/oauth2/service_account.py\", line 448, in refresh\n",
      "    access_token, expiry, _ = _client.jwt_grant(\n",
      "  File \"/Users/liting/Desktop/7940_GroupProject/.venv/lib/python3.10/site-packages/google/oauth2/_client.py\", line 299, in jwt_grant\n",
      "    response_data = _token_endpoint_request(\n",
      "  File \"/Users/liting/Desktop/7940_GroupProject/.venv/lib/python3.10/site-packages/google/oauth2/_client.py\", line 270, in _token_endpoint_request\n",
      "    _handle_error_response(response_data, retryable_error)\n",
      "  File \"/Users/liting/Desktop/7940_GroupProject/.venv/lib/python3.10/site-packages/google/oauth2/_client.py\", line 69, in _handle_error_response\n",
      "    raise exceptions.RefreshError(\n",
      "google.auth.exceptions.RefreshError: ('invalid_grant: Invalid JWT Signature.', {'error': 'invalid_grant', 'error_description': 'Invalid JWT Signature.'})\n",
      "ERROR:grpc._plugin_wrapping:AuthMetadataPluginCallback \"<google.auth.transport.grpc.AuthMetadataPlugin object at 0x1064fee00>\" raised exception!\n",
      "Traceback (most recent call last):\n",
      "  File \"/Users/liting/Desktop/7940_GroupProject/.venv/lib/python3.10/site-packages/grpc/_plugin_wrapping.py\", line 105, in __call__\n",
      "    self._metadata_plugin(\n",
      "  File \"/Users/liting/Desktop/7940_GroupProject/.venv/lib/python3.10/site-packages/google/auth/transport/grpc.py\", line 95, in __call__\n",
      "    callback(self._get_authorization_headers(context), None)\n",
      "  File \"/Users/liting/Desktop/7940_GroupProject/.venv/lib/python3.10/site-packages/google/auth/transport/grpc.py\", line 81, in _get_authorization_headers\n",
      "    self._credentials.before_request(\n",
      "  File \"/Users/liting/Desktop/7940_GroupProject/.venv/lib/python3.10/site-packages/google/auth/credentials.py\", line 239, in before_request\n",
      "    self._blocking_refresh(request)\n",
      "  File \"/Users/liting/Desktop/7940_GroupProject/.venv/lib/python3.10/site-packages/google/auth/credentials.py\", line 202, in _blocking_refresh\n",
      "    self.refresh(request)\n",
      "  File \"/Users/liting/Desktop/7940_GroupProject/.venv/lib/python3.10/site-packages/google/oauth2/service_account.py\", line 448, in refresh\n",
      "    access_token, expiry, _ = _client.jwt_grant(\n",
      "  File \"/Users/liting/Desktop/7940_GroupProject/.venv/lib/python3.10/site-packages/google/oauth2/_client.py\", line 299, in jwt_grant\n",
      "    response_data = _token_endpoint_request(\n",
      "  File \"/Users/liting/Desktop/7940_GroupProject/.venv/lib/python3.10/site-packages/google/oauth2/_client.py\", line 270, in _token_endpoint_request\n",
      "    _handle_error_response(response_data, retryable_error)\n",
      "  File \"/Users/liting/Desktop/7940_GroupProject/.venv/lib/python3.10/site-packages/google/oauth2/_client.py\", line 69, in _handle_error_response\n",
      "    raise exceptions.RefreshError(\n",
      "google.auth.exceptions.RefreshError: ('invalid_grant: Invalid JWT Signature.', {'error': 'invalid_grant', 'error_description': 'Invalid JWT Signature.'})\n",
      "ERROR:grpc._plugin_wrapping:AuthMetadataPluginCallback \"<google.auth.transport.grpc.AuthMetadataPlugin object at 0x1064fee00>\" raised exception!\n",
      "Traceback (most recent call last):\n",
      "  File \"/Users/liting/Desktop/7940_GroupProject/.venv/lib/python3.10/site-packages/grpc/_plugin_wrapping.py\", line 105, in __call__\n",
      "    self._metadata_plugin(\n",
      "  File \"/Users/liting/Desktop/7940_GroupProject/.venv/lib/python3.10/site-packages/google/auth/transport/grpc.py\", line 95, in __call__\n",
      "    callback(self._get_authorization_headers(context), None)\n",
      "  File \"/Users/liting/Desktop/7940_GroupProject/.venv/lib/python3.10/site-packages/google/auth/transport/grpc.py\", line 81, in _get_authorization_headers\n",
      "    self._credentials.before_request(\n",
      "  File \"/Users/liting/Desktop/7940_GroupProject/.venv/lib/python3.10/site-packages/google/auth/credentials.py\", line 239, in before_request\n",
      "    self._blocking_refresh(request)\n",
      "  File \"/Users/liting/Desktop/7940_GroupProject/.venv/lib/python3.10/site-packages/google/auth/credentials.py\", line 202, in _blocking_refresh\n",
      "    self.refresh(request)\n",
      "  File \"/Users/liting/Desktop/7940_GroupProject/.venv/lib/python3.10/site-packages/google/oauth2/service_account.py\", line 448, in refresh\n",
      "    access_token, expiry, _ = _client.jwt_grant(\n",
      "  File \"/Users/liting/Desktop/7940_GroupProject/.venv/lib/python3.10/site-packages/google/oauth2/_client.py\", line 299, in jwt_grant\n",
      "    response_data = _token_endpoint_request(\n",
      "  File \"/Users/liting/Desktop/7940_GroupProject/.venv/lib/python3.10/site-packages/google/oauth2/_client.py\", line 270, in _token_endpoint_request\n",
      "    _handle_error_response(response_data, retryable_error)\n",
      "  File \"/Users/liting/Desktop/7940_GroupProject/.venv/lib/python3.10/site-packages/google/oauth2/_client.py\", line 69, in _handle_error_response\n",
      "    raise exceptions.RefreshError(\n",
      "google.auth.exceptions.RefreshError: ('invalid_grant: Invalid JWT Signature.', {'error': 'invalid_grant', 'error_description': 'Invalid JWT Signature.'})\n",
      "ERROR:grpc._plugin_wrapping:AuthMetadataPluginCallback \"<google.auth.transport.grpc.AuthMetadataPlugin object at 0x1064fee00>\" raised exception!\n",
      "Traceback (most recent call last):\n",
      "  File \"/Users/liting/Desktop/7940_GroupProject/.venv/lib/python3.10/site-packages/grpc/_plugin_wrapping.py\", line 105, in __call__\n",
      "    self._metadata_plugin(\n",
      "  File \"/Users/liting/Desktop/7940_GroupProject/.venv/lib/python3.10/site-packages/google/auth/transport/grpc.py\", line 95, in __call__\n",
      "    callback(self._get_authorization_headers(context), None)\n",
      "  File \"/Users/liting/Desktop/7940_GroupProject/.venv/lib/python3.10/site-packages/google/auth/transport/grpc.py\", line 81, in _get_authorization_headers\n",
      "    self._credentials.before_request(\n",
      "  File \"/Users/liting/Desktop/7940_GroupProject/.venv/lib/python3.10/site-packages/google/auth/credentials.py\", line 239, in before_request\n",
      "    self._blocking_refresh(request)\n",
      "  File \"/Users/liting/Desktop/7940_GroupProject/.venv/lib/python3.10/site-packages/google/auth/credentials.py\", line 202, in _blocking_refresh\n",
      "    self.refresh(request)\n",
      "  File \"/Users/liting/Desktop/7940_GroupProject/.venv/lib/python3.10/site-packages/google/oauth2/service_account.py\", line 448, in refresh\n",
      "    access_token, expiry, _ = _client.jwt_grant(\n",
      "  File \"/Users/liting/Desktop/7940_GroupProject/.venv/lib/python3.10/site-packages/google/oauth2/_client.py\", line 299, in jwt_grant\n",
      "    response_data = _token_endpoint_request(\n",
      "  File \"/Users/liting/Desktop/7940_GroupProject/.venv/lib/python3.10/site-packages/google/oauth2/_client.py\", line 270, in _token_endpoint_request\n",
      "    _handle_error_response(response_data, retryable_error)\n",
      "  File \"/Users/liting/Desktop/7940_GroupProject/.venv/lib/python3.10/site-packages/google/oauth2/_client.py\", line 69, in _handle_error_response\n",
      "    raise exceptions.RefreshError(\n",
      "google.auth.exceptions.RefreshError: ('invalid_grant: Invalid JWT Signature.', {'error': 'invalid_grant', 'error_description': 'Invalid JWT Signature.'})\n",
      "ERROR:grpc._plugin_wrapping:AuthMetadataPluginCallback \"<google.auth.transport.grpc.AuthMetadataPlugin object at 0x1064fee00>\" raised exception!\n",
      "Traceback (most recent call last):\n",
      "  File \"/Users/liting/Desktop/7940_GroupProject/.venv/lib/python3.10/site-packages/grpc/_plugin_wrapping.py\", line 105, in __call__\n",
      "    self._metadata_plugin(\n",
      "  File \"/Users/liting/Desktop/7940_GroupProject/.venv/lib/python3.10/site-packages/google/auth/transport/grpc.py\", line 95, in __call__\n",
      "    callback(self._get_authorization_headers(context), None)\n",
      "  File \"/Users/liting/Desktop/7940_GroupProject/.venv/lib/python3.10/site-packages/google/auth/transport/grpc.py\", line 81, in _get_authorization_headers\n",
      "    self._credentials.before_request(\n",
      "  File \"/Users/liting/Desktop/7940_GroupProject/.venv/lib/python3.10/site-packages/google/auth/credentials.py\", line 239, in before_request\n",
      "    self._blocking_refresh(request)\n",
      "  File \"/Users/liting/Desktop/7940_GroupProject/.venv/lib/python3.10/site-packages/google/auth/credentials.py\", line 202, in _blocking_refresh\n",
      "    self.refresh(request)\n",
      "  File \"/Users/liting/Desktop/7940_GroupProject/.venv/lib/python3.10/site-packages/google/oauth2/service_account.py\", line 448, in refresh\n",
      "    access_token, expiry, _ = _client.jwt_grant(\n",
      "  File \"/Users/liting/Desktop/7940_GroupProject/.venv/lib/python3.10/site-packages/google/oauth2/_client.py\", line 299, in jwt_grant\n",
      "    response_data = _token_endpoint_request(\n",
      "  File \"/Users/liting/Desktop/7940_GroupProject/.venv/lib/python3.10/site-packages/google/oauth2/_client.py\", line 270, in _token_endpoint_request\n",
      "    _handle_error_response(response_data, retryable_error)\n",
      "  File \"/Users/liting/Desktop/7940_GroupProject/.venv/lib/python3.10/site-packages/google/oauth2/_client.py\", line 69, in _handle_error_response\n",
      "    raise exceptions.RefreshError(\n",
      "google.auth.exceptions.RefreshError: ('invalid_grant: Invalid JWT Signature.', {'error': 'invalid_grant', 'error_description': 'Invalid JWT Signature.'})\n",
      "ERROR:grpc._plugin_wrapping:AuthMetadataPluginCallback \"<google.auth.transport.grpc.AuthMetadataPlugin object at 0x1064fee00>\" raised exception!\n",
      "Traceback (most recent call last):\n",
      "  File \"/Users/liting/Desktop/7940_GroupProject/.venv/lib/python3.10/site-packages/grpc/_plugin_wrapping.py\", line 105, in __call__\n",
      "    self._metadata_plugin(\n",
      "  File \"/Users/liting/Desktop/7940_GroupProject/.venv/lib/python3.10/site-packages/google/auth/transport/grpc.py\", line 95, in __call__\n",
      "    callback(self._get_authorization_headers(context), None)\n",
      "  File \"/Users/liting/Desktop/7940_GroupProject/.venv/lib/python3.10/site-packages/google/auth/transport/grpc.py\", line 81, in _get_authorization_headers\n",
      "    self._credentials.before_request(\n",
      "  File \"/Users/liting/Desktop/7940_GroupProject/.venv/lib/python3.10/site-packages/google/auth/credentials.py\", line 239, in before_request\n",
      "    self._blocking_refresh(request)\n",
      "  File \"/Users/liting/Desktop/7940_GroupProject/.venv/lib/python3.10/site-packages/google/auth/credentials.py\", line 202, in _blocking_refresh\n",
      "    self.refresh(request)\n",
      "  File \"/Users/liting/Desktop/7940_GroupProject/.venv/lib/python3.10/site-packages/google/oauth2/service_account.py\", line 448, in refresh\n",
      "    access_token, expiry, _ = _client.jwt_grant(\n",
      "  File \"/Users/liting/Desktop/7940_GroupProject/.venv/lib/python3.10/site-packages/google/oauth2/_client.py\", line 299, in jwt_grant\n",
      "    response_data = _token_endpoint_request(\n",
      "  File \"/Users/liting/Desktop/7940_GroupProject/.venv/lib/python3.10/site-packages/google/oauth2/_client.py\", line 270, in _token_endpoint_request\n",
      "    _handle_error_response(response_data, retryable_error)\n",
      "  File \"/Users/liting/Desktop/7940_GroupProject/.venv/lib/python3.10/site-packages/google/oauth2/_client.py\", line 69, in _handle_error_response\n",
      "    raise exceptions.RefreshError(\n",
      "google.auth.exceptions.RefreshError: ('invalid_grant: Invalid JWT Signature.', {'error': 'invalid_grant', 'error_description': 'Invalid JWT Signature.'})\n",
      "ERROR:grpc._plugin_wrapping:AuthMetadataPluginCallback \"<google.auth.transport.grpc.AuthMetadataPlugin object at 0x1064fee00>\" raised exception!\n",
      "Traceback (most recent call last):\n",
      "  File \"/Users/liting/Desktop/7940_GroupProject/.venv/lib/python3.10/site-packages/grpc/_plugin_wrapping.py\", line 105, in __call__\n",
      "    self._metadata_plugin(\n",
      "  File \"/Users/liting/Desktop/7940_GroupProject/.venv/lib/python3.10/site-packages/google/auth/transport/grpc.py\", line 95, in __call__\n",
      "    callback(self._get_authorization_headers(context), None)\n",
      "  File \"/Users/liting/Desktop/7940_GroupProject/.venv/lib/python3.10/site-packages/google/auth/transport/grpc.py\", line 81, in _get_authorization_headers\n",
      "    self._credentials.before_request(\n",
      "  File \"/Users/liting/Desktop/7940_GroupProject/.venv/lib/python3.10/site-packages/google/auth/credentials.py\", line 239, in before_request\n",
      "    self._blocking_refresh(request)\n",
      "  File \"/Users/liting/Desktop/7940_GroupProject/.venv/lib/python3.10/site-packages/google/auth/credentials.py\", line 202, in _blocking_refresh\n",
      "    self.refresh(request)\n",
      "  File \"/Users/liting/Desktop/7940_GroupProject/.venv/lib/python3.10/site-packages/google/oauth2/service_account.py\", line 448, in refresh\n",
      "    access_token, expiry, _ = _client.jwt_grant(\n",
      "  File \"/Users/liting/Desktop/7940_GroupProject/.venv/lib/python3.10/site-packages/google/oauth2/_client.py\", line 299, in jwt_grant\n",
      "    response_data = _token_endpoint_request(\n",
      "  File \"/Users/liting/Desktop/7940_GroupProject/.venv/lib/python3.10/site-packages/google/oauth2/_client.py\", line 270, in _token_endpoint_request\n",
      "    _handle_error_response(response_data, retryable_error)\n",
      "  File \"/Users/liting/Desktop/7940_GroupProject/.venv/lib/python3.10/site-packages/google/oauth2/_client.py\", line 69, in _handle_error_response\n",
      "    raise exceptions.RefreshError(\n",
      "google.auth.exceptions.RefreshError: ('invalid_grant: Invalid JWT Signature.', {'error': 'invalid_grant', 'error_description': 'Invalid JWT Signature.'})\n",
      "ERROR:grpc._plugin_wrapping:AuthMetadataPluginCallback \"<google.auth.transport.grpc.AuthMetadataPlugin object at 0x1064fee00>\" raised exception!\n",
      "Traceback (most recent call last):\n",
      "  File \"/Users/liting/Desktop/7940_GroupProject/.venv/lib/python3.10/site-packages/grpc/_plugin_wrapping.py\", line 105, in __call__\n",
      "    self._metadata_plugin(\n",
      "  File \"/Users/liting/Desktop/7940_GroupProject/.venv/lib/python3.10/site-packages/google/auth/transport/grpc.py\", line 95, in __call__\n",
      "    callback(self._get_authorization_headers(context), None)\n",
      "  File \"/Users/liting/Desktop/7940_GroupProject/.venv/lib/python3.10/site-packages/google/auth/transport/grpc.py\", line 81, in _get_authorization_headers\n",
      "    self._credentials.before_request(\n",
      "  File \"/Users/liting/Desktop/7940_GroupProject/.venv/lib/python3.10/site-packages/google/auth/credentials.py\", line 239, in before_request\n",
      "    self._blocking_refresh(request)\n",
      "  File \"/Users/liting/Desktop/7940_GroupProject/.venv/lib/python3.10/site-packages/google/auth/credentials.py\", line 202, in _blocking_refresh\n",
      "    self.refresh(request)\n",
      "  File \"/Users/liting/Desktop/7940_GroupProject/.venv/lib/python3.10/site-packages/google/oauth2/service_account.py\", line 448, in refresh\n",
      "    access_token, expiry, _ = _client.jwt_grant(\n",
      "  File \"/Users/liting/Desktop/7940_GroupProject/.venv/lib/python3.10/site-packages/google/oauth2/_client.py\", line 299, in jwt_grant\n",
      "    response_data = _token_endpoint_request(\n",
      "  File \"/Users/liting/Desktop/7940_GroupProject/.venv/lib/python3.10/site-packages/google/oauth2/_client.py\", line 270, in _token_endpoint_request\n",
      "    _handle_error_response(response_data, retryable_error)\n",
      "  File \"/Users/liting/Desktop/7940_GroupProject/.venv/lib/python3.10/site-packages/google/oauth2/_client.py\", line 69, in _handle_error_response\n",
      "    raise exceptions.RefreshError(\n",
      "google.auth.exceptions.RefreshError: ('invalid_grant: Invalid JWT Signature.', {'error': 'invalid_grant', 'error_description': 'Invalid JWT Signature.'})\n",
      "ERROR:grpc._plugin_wrapping:AuthMetadataPluginCallback \"<google.auth.transport.grpc.AuthMetadataPlugin object at 0x1064fee00>\" raised exception!\n",
      "Traceback (most recent call last):\n",
      "  File \"/Users/liting/Desktop/7940_GroupProject/.venv/lib/python3.10/site-packages/grpc/_plugin_wrapping.py\", line 105, in __call__\n",
      "    self._metadata_plugin(\n",
      "  File \"/Users/liting/Desktop/7940_GroupProject/.venv/lib/python3.10/site-packages/google/auth/transport/grpc.py\", line 95, in __call__\n",
      "    callback(self._get_authorization_headers(context), None)\n",
      "  File \"/Users/liting/Desktop/7940_GroupProject/.venv/lib/python3.10/site-packages/google/auth/transport/grpc.py\", line 81, in _get_authorization_headers\n",
      "    self._credentials.before_request(\n",
      "  File \"/Users/liting/Desktop/7940_GroupProject/.venv/lib/python3.10/site-packages/google/auth/credentials.py\", line 239, in before_request\n",
      "    self._blocking_refresh(request)\n",
      "  File \"/Users/liting/Desktop/7940_GroupProject/.venv/lib/python3.10/site-packages/google/auth/credentials.py\", line 202, in _blocking_refresh\n",
      "    self.refresh(request)\n",
      "  File \"/Users/liting/Desktop/7940_GroupProject/.venv/lib/python3.10/site-packages/google/oauth2/service_account.py\", line 448, in refresh\n",
      "    access_token, expiry, _ = _client.jwt_grant(\n",
      "  File \"/Users/liting/Desktop/7940_GroupProject/.venv/lib/python3.10/site-packages/google/oauth2/_client.py\", line 299, in jwt_grant\n",
      "    response_data = _token_endpoint_request(\n",
      "  File \"/Users/liting/Desktop/7940_GroupProject/.venv/lib/python3.10/site-packages/google/oauth2/_client.py\", line 270, in _token_endpoint_request\n",
      "    _handle_error_response(response_data, retryable_error)\n",
      "  File \"/Users/liting/Desktop/7940_GroupProject/.venv/lib/python3.10/site-packages/google/oauth2/_client.py\", line 69, in _handle_error_response\n",
      "    raise exceptions.RefreshError(\n",
      "google.auth.exceptions.RefreshError: ('invalid_grant: Invalid JWT Signature.', {'error': 'invalid_grant', 'error_description': 'Invalid JWT Signature.'})\n",
      "ERROR:grpc._plugin_wrapping:AuthMetadataPluginCallback \"<google.auth.transport.grpc.AuthMetadataPlugin object at 0x1064fee00>\" raised exception!\n",
      "Traceback (most recent call last):\n",
      "  File \"/Users/liting/Desktop/7940_GroupProject/.venv/lib/python3.10/site-packages/grpc/_plugin_wrapping.py\", line 105, in __call__\n",
      "    self._metadata_plugin(\n",
      "  File \"/Users/liting/Desktop/7940_GroupProject/.venv/lib/python3.10/site-packages/google/auth/transport/grpc.py\", line 95, in __call__\n",
      "    callback(self._get_authorization_headers(context), None)\n",
      "  File \"/Users/liting/Desktop/7940_GroupProject/.venv/lib/python3.10/site-packages/google/auth/transport/grpc.py\", line 81, in _get_authorization_headers\n",
      "    self._credentials.before_request(\n",
      "  File \"/Users/liting/Desktop/7940_GroupProject/.venv/lib/python3.10/site-packages/google/auth/credentials.py\", line 239, in before_request\n",
      "    self._blocking_refresh(request)\n",
      "  File \"/Users/liting/Desktop/7940_GroupProject/.venv/lib/python3.10/site-packages/google/auth/credentials.py\", line 202, in _blocking_refresh\n",
      "    self.refresh(request)\n",
      "  File \"/Users/liting/Desktop/7940_GroupProject/.venv/lib/python3.10/site-packages/google/oauth2/service_account.py\", line 448, in refresh\n",
      "    access_token, expiry, _ = _client.jwt_grant(\n",
      "  File \"/Users/liting/Desktop/7940_GroupProject/.venv/lib/python3.10/site-packages/google/oauth2/_client.py\", line 299, in jwt_grant\n",
      "    response_data = _token_endpoint_request(\n",
      "  File \"/Users/liting/Desktop/7940_GroupProject/.venv/lib/python3.10/site-packages/google/oauth2/_client.py\", line 270, in _token_endpoint_request\n",
      "    _handle_error_response(response_data, retryable_error)\n",
      "  File \"/Users/liting/Desktop/7940_GroupProject/.venv/lib/python3.10/site-packages/google/oauth2/_client.py\", line 69, in _handle_error_response\n",
      "    raise exceptions.RefreshError(\n",
      "google.auth.exceptions.RefreshError: ('invalid_grant: Invalid JWT Signature.', {'error': 'invalid_grant', 'error_description': 'Invalid JWT Signature.'})\n",
      "ERROR:grpc._plugin_wrapping:AuthMetadataPluginCallback \"<google.auth.transport.grpc.AuthMetadataPlugin object at 0x1064fee00>\" raised exception!\n",
      "Traceback (most recent call last):\n",
      "  File \"/Users/liting/Desktop/7940_GroupProject/.venv/lib/python3.10/site-packages/grpc/_plugin_wrapping.py\", line 105, in __call__\n",
      "    self._metadata_plugin(\n",
      "  File \"/Users/liting/Desktop/7940_GroupProject/.venv/lib/python3.10/site-packages/google/auth/transport/grpc.py\", line 95, in __call__\n",
      "    callback(self._get_authorization_headers(context), None)\n",
      "  File \"/Users/liting/Desktop/7940_GroupProject/.venv/lib/python3.10/site-packages/google/auth/transport/grpc.py\", line 81, in _get_authorization_headers\n",
      "    self._credentials.before_request(\n",
      "  File \"/Users/liting/Desktop/7940_GroupProject/.venv/lib/python3.10/site-packages/google/auth/credentials.py\", line 239, in before_request\n",
      "    self._blocking_refresh(request)\n",
      "  File \"/Users/liting/Desktop/7940_GroupProject/.venv/lib/python3.10/site-packages/google/auth/credentials.py\", line 202, in _blocking_refresh\n",
      "    self.refresh(request)\n",
      "  File \"/Users/liting/Desktop/7940_GroupProject/.venv/lib/python3.10/site-packages/google/oauth2/service_account.py\", line 448, in refresh\n",
      "    access_token, expiry, _ = _client.jwt_grant(\n",
      "  File \"/Users/liting/Desktop/7940_GroupProject/.venv/lib/python3.10/site-packages/google/oauth2/_client.py\", line 299, in jwt_grant\n",
      "    response_data = _token_endpoint_request(\n",
      "  File \"/Users/liting/Desktop/7940_GroupProject/.venv/lib/python3.10/site-packages/google/oauth2/_client.py\", line 270, in _token_endpoint_request\n",
      "    _handle_error_response(response_data, retryable_error)\n",
      "  File \"/Users/liting/Desktop/7940_GroupProject/.venv/lib/python3.10/site-packages/google/oauth2/_client.py\", line 69, in _handle_error_response\n",
      "    raise exceptions.RefreshError(\n",
      "google.auth.exceptions.RefreshError: ('invalid_grant: Invalid JWT Signature.', {'error': 'invalid_grant', 'error_description': 'Invalid JWT Signature.'})\n",
      "ERROR:grpc._plugin_wrapping:AuthMetadataPluginCallback \"<google.auth.transport.grpc.AuthMetadataPlugin object at 0x1064fee00>\" raised exception!\n",
      "Traceback (most recent call last):\n",
      "  File \"/Users/liting/Desktop/7940_GroupProject/.venv/lib/python3.10/site-packages/grpc/_plugin_wrapping.py\", line 105, in __call__\n",
      "    self._metadata_plugin(\n",
      "  File \"/Users/liting/Desktop/7940_GroupProject/.venv/lib/python3.10/site-packages/google/auth/transport/grpc.py\", line 95, in __call__\n",
      "    callback(self._get_authorization_headers(context), None)\n",
      "  File \"/Users/liting/Desktop/7940_GroupProject/.venv/lib/python3.10/site-packages/google/auth/transport/grpc.py\", line 81, in _get_authorization_headers\n",
      "    self._credentials.before_request(\n",
      "  File \"/Users/liting/Desktop/7940_GroupProject/.venv/lib/python3.10/site-packages/google/auth/credentials.py\", line 239, in before_request\n",
      "    self._blocking_refresh(request)\n",
      "  File \"/Users/liting/Desktop/7940_GroupProject/.venv/lib/python3.10/site-packages/google/auth/credentials.py\", line 202, in _blocking_refresh\n",
      "    self.refresh(request)\n",
      "  File \"/Users/liting/Desktop/7940_GroupProject/.venv/lib/python3.10/site-packages/google/oauth2/service_account.py\", line 448, in refresh\n",
      "    access_token, expiry, _ = _client.jwt_grant(\n",
      "  File \"/Users/liting/Desktop/7940_GroupProject/.venv/lib/python3.10/site-packages/google/oauth2/_client.py\", line 299, in jwt_grant\n",
      "    response_data = _token_endpoint_request(\n",
      "  File \"/Users/liting/Desktop/7940_GroupProject/.venv/lib/python3.10/site-packages/google/oauth2/_client.py\", line 270, in _token_endpoint_request\n",
      "    _handle_error_response(response_data, retryable_error)\n",
      "  File \"/Users/liting/Desktop/7940_GroupProject/.venv/lib/python3.10/site-packages/google/oauth2/_client.py\", line 69, in _handle_error_response\n",
      "    raise exceptions.RefreshError(\n",
      "google.auth.exceptions.RefreshError: ('invalid_grant: Invalid JWT Signature.', {'error': 'invalid_grant', 'error_description': 'Invalid JWT Signature.'})\n",
      "ERROR:grpc._plugin_wrapping:AuthMetadataPluginCallback \"<google.auth.transport.grpc.AuthMetadataPlugin object at 0x1064fee00>\" raised exception!\n",
      "Traceback (most recent call last):\n",
      "  File \"/Users/liting/Desktop/7940_GroupProject/.venv/lib/python3.10/site-packages/grpc/_plugin_wrapping.py\", line 105, in __call__\n",
      "    self._metadata_plugin(\n",
      "  File \"/Users/liting/Desktop/7940_GroupProject/.venv/lib/python3.10/site-packages/google/auth/transport/grpc.py\", line 95, in __call__\n",
      "    callback(self._get_authorization_headers(context), None)\n",
      "  File \"/Users/liting/Desktop/7940_GroupProject/.venv/lib/python3.10/site-packages/google/auth/transport/grpc.py\", line 81, in _get_authorization_headers\n",
      "    self._credentials.before_request(\n",
      "  File \"/Users/liting/Desktop/7940_GroupProject/.venv/lib/python3.10/site-packages/google/auth/credentials.py\", line 239, in before_request\n",
      "    self._blocking_refresh(request)\n",
      "  File \"/Users/liting/Desktop/7940_GroupProject/.venv/lib/python3.10/site-packages/google/auth/credentials.py\", line 202, in _blocking_refresh\n",
      "    self.refresh(request)\n",
      "  File \"/Users/liting/Desktop/7940_GroupProject/.venv/lib/python3.10/site-packages/google/oauth2/service_account.py\", line 448, in refresh\n",
      "    access_token, expiry, _ = _client.jwt_grant(\n",
      "  File \"/Users/liting/Desktop/7940_GroupProject/.venv/lib/python3.10/site-packages/google/oauth2/_client.py\", line 299, in jwt_grant\n",
      "    response_data = _token_endpoint_request(\n",
      "  File \"/Users/liting/Desktop/7940_GroupProject/.venv/lib/python3.10/site-packages/google/oauth2/_client.py\", line 270, in _token_endpoint_request\n",
      "    _handle_error_response(response_data, retryable_error)\n",
      "  File \"/Users/liting/Desktop/7940_GroupProject/.venv/lib/python3.10/site-packages/google/oauth2/_client.py\", line 69, in _handle_error_response\n",
      "    raise exceptions.RefreshError(\n",
      "google.auth.exceptions.RefreshError: ('invalid_grant: Invalid JWT Signature.', {'error': 'invalid_grant', 'error_description': 'Invalid JWT Signature.'})\n",
      "ERROR:grpc._plugin_wrapping:AuthMetadataPluginCallback \"<google.auth.transport.grpc.AuthMetadataPlugin object at 0x1064fee00>\" raised exception!\n",
      "Traceback (most recent call last):\n",
      "  File \"/Users/liting/Desktop/7940_GroupProject/.venv/lib/python3.10/site-packages/grpc/_plugin_wrapping.py\", line 105, in __call__\n",
      "    self._metadata_plugin(\n",
      "  File \"/Users/liting/Desktop/7940_GroupProject/.venv/lib/python3.10/site-packages/google/auth/transport/grpc.py\", line 95, in __call__\n",
      "    callback(self._get_authorization_headers(context), None)\n",
      "  File \"/Users/liting/Desktop/7940_GroupProject/.venv/lib/python3.10/site-packages/google/auth/transport/grpc.py\", line 81, in _get_authorization_headers\n",
      "    self._credentials.before_request(\n",
      "  File \"/Users/liting/Desktop/7940_GroupProject/.venv/lib/python3.10/site-packages/google/auth/credentials.py\", line 239, in before_request\n",
      "    self._blocking_refresh(request)\n",
      "  File \"/Users/liting/Desktop/7940_GroupProject/.venv/lib/python3.10/site-packages/google/auth/credentials.py\", line 202, in _blocking_refresh\n",
      "    self.refresh(request)\n",
      "  File \"/Users/liting/Desktop/7940_GroupProject/.venv/lib/python3.10/site-packages/google/oauth2/service_account.py\", line 448, in refresh\n",
      "    access_token, expiry, _ = _client.jwt_grant(\n",
      "  File \"/Users/liting/Desktop/7940_GroupProject/.venv/lib/python3.10/site-packages/google/oauth2/_client.py\", line 299, in jwt_grant\n",
      "    response_data = _token_endpoint_request(\n",
      "  File \"/Users/liting/Desktop/7940_GroupProject/.venv/lib/python3.10/site-packages/google/oauth2/_client.py\", line 270, in _token_endpoint_request\n",
      "    _handle_error_response(response_data, retryable_error)\n",
      "  File \"/Users/liting/Desktop/7940_GroupProject/.venv/lib/python3.10/site-packages/google/oauth2/_client.py\", line 69, in _handle_error_response\n",
      "    raise exceptions.RefreshError(\n",
      "google.auth.exceptions.RefreshError: ('invalid_grant: Invalid JWT Signature.', {'error': 'invalid_grant', 'error_description': 'Invalid JWT Signature.'})\n",
      "ERROR:grpc._plugin_wrapping:AuthMetadataPluginCallback \"<google.auth.transport.grpc.AuthMetadataPlugin object at 0x1064fee00>\" raised exception!\n",
      "Traceback (most recent call last):\n",
      "  File \"/Users/liting/Desktop/7940_GroupProject/.venv/lib/python3.10/site-packages/grpc/_plugin_wrapping.py\", line 105, in __call__\n",
      "    self._metadata_plugin(\n",
      "  File \"/Users/liting/Desktop/7940_GroupProject/.venv/lib/python3.10/site-packages/google/auth/transport/grpc.py\", line 95, in __call__\n",
      "    callback(self._get_authorization_headers(context), None)\n",
      "  File \"/Users/liting/Desktop/7940_GroupProject/.venv/lib/python3.10/site-packages/google/auth/transport/grpc.py\", line 81, in _get_authorization_headers\n",
      "    self._credentials.before_request(\n",
      "  File \"/Users/liting/Desktop/7940_GroupProject/.venv/lib/python3.10/site-packages/google/auth/credentials.py\", line 239, in before_request\n",
      "    self._blocking_refresh(request)\n",
      "  File \"/Users/liting/Desktop/7940_GroupProject/.venv/lib/python3.10/site-packages/google/auth/credentials.py\", line 202, in _blocking_refresh\n",
      "    self.refresh(request)\n",
      "  File \"/Users/liting/Desktop/7940_GroupProject/.venv/lib/python3.10/site-packages/google/oauth2/service_account.py\", line 448, in refresh\n",
      "    access_token, expiry, _ = _client.jwt_grant(\n",
      "  File \"/Users/liting/Desktop/7940_GroupProject/.venv/lib/python3.10/site-packages/google/oauth2/_client.py\", line 299, in jwt_grant\n",
      "    response_data = _token_endpoint_request(\n",
      "  File \"/Users/liting/Desktop/7940_GroupProject/.venv/lib/python3.10/site-packages/google/oauth2/_client.py\", line 270, in _token_endpoint_request\n",
      "    _handle_error_response(response_data, retryable_error)\n",
      "  File \"/Users/liting/Desktop/7940_GroupProject/.venv/lib/python3.10/site-packages/google/oauth2/_client.py\", line 69, in _handle_error_response\n",
      "    raise exceptions.RefreshError(\n",
      "google.auth.exceptions.RefreshError: ('invalid_grant: Invalid JWT Signature.', {'error': 'invalid_grant', 'error_description': 'Invalid JWT Signature.'})\n",
      "ERROR:grpc._plugin_wrapping:AuthMetadataPluginCallback \"<google.auth.transport.grpc.AuthMetadataPlugin object at 0x1064fee00>\" raised exception!\n",
      "Traceback (most recent call last):\n",
      "  File \"/Users/liting/Desktop/7940_GroupProject/.venv/lib/python3.10/site-packages/grpc/_plugin_wrapping.py\", line 105, in __call__\n",
      "    self._metadata_plugin(\n",
      "  File \"/Users/liting/Desktop/7940_GroupProject/.venv/lib/python3.10/site-packages/google/auth/transport/grpc.py\", line 95, in __call__\n",
      "    callback(self._get_authorization_headers(context), None)\n",
      "  File \"/Users/liting/Desktop/7940_GroupProject/.venv/lib/python3.10/site-packages/google/auth/transport/grpc.py\", line 81, in _get_authorization_headers\n",
      "    self._credentials.before_request(\n",
      "  File \"/Users/liting/Desktop/7940_GroupProject/.venv/lib/python3.10/site-packages/google/auth/credentials.py\", line 239, in before_request\n",
      "    self._blocking_refresh(request)\n",
      "  File \"/Users/liting/Desktop/7940_GroupProject/.venv/lib/python3.10/site-packages/google/auth/credentials.py\", line 202, in _blocking_refresh\n",
      "    self.refresh(request)\n",
      "  File \"/Users/liting/Desktop/7940_GroupProject/.venv/lib/python3.10/site-packages/google/oauth2/service_account.py\", line 448, in refresh\n",
      "    access_token, expiry, _ = _client.jwt_grant(\n",
      "  File \"/Users/liting/Desktop/7940_GroupProject/.venv/lib/python3.10/site-packages/google/oauth2/_client.py\", line 299, in jwt_grant\n",
      "    response_data = _token_endpoint_request(\n",
      "  File \"/Users/liting/Desktop/7940_GroupProject/.venv/lib/python3.10/site-packages/google/oauth2/_client.py\", line 270, in _token_endpoint_request\n",
      "    _handle_error_response(response_data, retryable_error)\n",
      "  File \"/Users/liting/Desktop/7940_GroupProject/.venv/lib/python3.10/site-packages/google/oauth2/_client.py\", line 69, in _handle_error_response\n",
      "    raise exceptions.RefreshError(\n",
      "google.auth.exceptions.RefreshError: ('invalid_grant: Invalid JWT Signature.', {'error': 'invalid_grant', 'error_description': 'Invalid JWT Signature.'})\n",
      "ERROR:grpc._plugin_wrapping:AuthMetadataPluginCallback \"<google.auth.transport.grpc.AuthMetadataPlugin object at 0x1064fee00>\" raised exception!\n",
      "Traceback (most recent call last):\n",
      "  File \"/Users/liting/Desktop/7940_GroupProject/.venv/lib/python3.10/site-packages/grpc/_plugin_wrapping.py\", line 105, in __call__\n",
      "    self._metadata_plugin(\n",
      "  File \"/Users/liting/Desktop/7940_GroupProject/.venv/lib/python3.10/site-packages/google/auth/transport/grpc.py\", line 95, in __call__\n",
      "    callback(self._get_authorization_headers(context), None)\n",
      "  File \"/Users/liting/Desktop/7940_GroupProject/.venv/lib/python3.10/site-packages/google/auth/transport/grpc.py\", line 81, in _get_authorization_headers\n",
      "    self._credentials.before_request(\n",
      "  File \"/Users/liting/Desktop/7940_GroupProject/.venv/lib/python3.10/site-packages/google/auth/credentials.py\", line 239, in before_request\n",
      "    self._blocking_refresh(request)\n",
      "  File \"/Users/liting/Desktop/7940_GroupProject/.venv/lib/python3.10/site-packages/google/auth/credentials.py\", line 202, in _blocking_refresh\n",
      "    self.refresh(request)\n",
      "  File \"/Users/liting/Desktop/7940_GroupProject/.venv/lib/python3.10/site-packages/google/oauth2/service_account.py\", line 448, in refresh\n",
      "    access_token, expiry, _ = _client.jwt_grant(\n",
      "  File \"/Users/liting/Desktop/7940_GroupProject/.venv/lib/python3.10/site-packages/google/oauth2/_client.py\", line 299, in jwt_grant\n",
      "    response_data = _token_endpoint_request(\n",
      "  File \"/Users/liting/Desktop/7940_GroupProject/.venv/lib/python3.10/site-packages/google/oauth2/_client.py\", line 270, in _token_endpoint_request\n",
      "    _handle_error_response(response_data, retryable_error)\n",
      "  File \"/Users/liting/Desktop/7940_GroupProject/.venv/lib/python3.10/site-packages/google/oauth2/_client.py\", line 69, in _handle_error_response\n",
      "    raise exceptions.RefreshError(\n",
      "google.auth.exceptions.RefreshError: ('invalid_grant: Invalid JWT Signature.', {'error': 'invalid_grant', 'error_description': 'Invalid JWT Signature.'})\n",
      "ERROR:grpc._plugin_wrapping:AuthMetadataPluginCallback \"<google.auth.transport.grpc.AuthMetadataPlugin object at 0x1064fee00>\" raised exception!\n",
      "Traceback (most recent call last):\n",
      "  File \"/Users/liting/Desktop/7940_GroupProject/.venv/lib/python3.10/site-packages/grpc/_plugin_wrapping.py\", line 105, in __call__\n",
      "    self._metadata_plugin(\n",
      "  File \"/Users/liting/Desktop/7940_GroupProject/.venv/lib/python3.10/site-packages/google/auth/transport/grpc.py\", line 95, in __call__\n",
      "    callback(self._get_authorization_headers(context), None)\n",
      "  File \"/Users/liting/Desktop/7940_GroupProject/.venv/lib/python3.10/site-packages/google/auth/transport/grpc.py\", line 81, in _get_authorization_headers\n",
      "    self._credentials.before_request(\n",
      "  File \"/Users/liting/Desktop/7940_GroupProject/.venv/lib/python3.10/site-packages/google/auth/credentials.py\", line 239, in before_request\n",
      "    self._blocking_refresh(request)\n",
      "  File \"/Users/liting/Desktop/7940_GroupProject/.venv/lib/python3.10/site-packages/google/auth/credentials.py\", line 202, in _blocking_refresh\n",
      "    self.refresh(request)\n",
      "  File \"/Users/liting/Desktop/7940_GroupProject/.venv/lib/python3.10/site-packages/google/oauth2/service_account.py\", line 448, in refresh\n",
      "    access_token, expiry, _ = _client.jwt_grant(\n",
      "  File \"/Users/liting/Desktop/7940_GroupProject/.venv/lib/python3.10/site-packages/google/oauth2/_client.py\", line 299, in jwt_grant\n",
      "    response_data = _token_endpoint_request(\n",
      "  File \"/Users/liting/Desktop/7940_GroupProject/.venv/lib/python3.10/site-packages/google/oauth2/_client.py\", line 270, in _token_endpoint_request\n",
      "    _handle_error_response(response_data, retryable_error)\n",
      "  File \"/Users/liting/Desktop/7940_GroupProject/.venv/lib/python3.10/site-packages/google/oauth2/_client.py\", line 69, in _handle_error_response\n",
      "    raise exceptions.RefreshError(\n",
      "google.auth.exceptions.RefreshError: ('invalid_grant: Invalid JWT Signature.', {'error': 'invalid_grant', 'error_description': 'Invalid JWT Signature.'})\n",
      "ERROR:telegram.ext.dispatcher:No error handlers are registered, logging exception.\n",
      "Traceback (most recent call last):\n",
      "  File \"/Users/liting/Desktop/7940_GroupProject/.venv/lib/python3.10/site-packages/google/api_core/grpc_helpers.py\", line 76, in error_remapped_callable\n",
      "    return callable_(*args, **kwargs)\n",
      "  File \"/Users/liting/Desktop/7940_GroupProject/.venv/lib/python3.10/site-packages/grpc/_interceptor.py\", line 277, in __call__\n",
      "    response, ignored_call = self._with_call(\n",
      "  File \"/Users/liting/Desktop/7940_GroupProject/.venv/lib/python3.10/site-packages/grpc/_interceptor.py\", line 332, in _with_call\n",
      "    return call.result(), call\n",
      "  File \"/Users/liting/Desktop/7940_GroupProject/.venv/lib/python3.10/site-packages/grpc/_channel.py\", line 440, in result\n",
      "    raise self\n",
      "  File \"/Users/liting/Desktop/7940_GroupProject/.venv/lib/python3.10/site-packages/grpc/_interceptor.py\", line 315, in continuation\n",
      "    response, call = self._thunk(new_method).with_call(\n",
      "  File \"/Users/liting/Desktop/7940_GroupProject/.venv/lib/python3.10/site-packages/grpc/_channel.py\", line 1198, in with_call\n",
      "    return _end_unary_response_blocking(state, call, True, None)\n",
      "  File \"/Users/liting/Desktop/7940_GroupProject/.venv/lib/python3.10/site-packages/grpc/_channel.py\", line 1006, in _end_unary_response_blocking\n",
      "    raise _InactiveRpcError(state)  # pytype: disable=not-instantiable\n",
      "grpc._channel._InactiveRpcError: <_InactiveRpcError of RPC that terminated with:\n",
      "\tstatus = StatusCode.UNAVAILABLE\n",
      "\tdetails = \"Getting metadata from plugin failed with error: ('invalid_grant: Invalid JWT Signature.', {'error': 'invalid_grant', 'error_description': 'Invalid JWT Signature.'})\"\n",
      "\tdebug_error_string = \"UNKNOWN:Error received from peer  {grpc_message:\"Getting metadata from plugin failed with error: (\\'invalid_grant: Invalid JWT Signature.\\', {\\'error\\': \\'invalid_grant\\', \\'error_description\\': \\'Invalid JWT Signature.\\'})\", grpc_status:14, created_time:\"2025-04-06T10:24:29.108709+08:00\"}\"\n",
      ">\n",
      "\n",
      "The above exception was the direct cause of the following exception:\n",
      "\n",
      "Traceback (most recent call last):\n",
      "  File \"/Users/liting/Desktop/7940_GroupProject/.venv/lib/python3.10/site-packages/google/api_core/retry/retry_unary.py\", line 144, in retry_target\n",
      "    result = target()\n",
      "  File \"/Users/liting/Desktop/7940_GroupProject/.venv/lib/python3.10/site-packages/google/api_core/timeout.py\", line 130, in func_with_timeout\n",
      "    return func(*args, **kwargs)\n",
      "  File \"/Users/liting/Desktop/7940_GroupProject/.venv/lib/python3.10/site-packages/google/api_core/grpc_helpers.py\", line 78, in error_remapped_callable\n",
      "    raise exceptions.from_grpc_error(exc) from exc\n",
      "google.api_core.exceptions.ServiceUnavailable: 503 Getting metadata from plugin failed with error: ('invalid_grant: Invalid JWT Signature.', {'error': 'invalid_grant', 'error_description': 'Invalid JWT Signature.'})\n",
      "\n",
      "The above exception was the direct cause of the following exception:\n",
      "\n",
      "Traceback (most recent call last):\n",
      "  File \"/Users/liting/Desktop/7940_GroupProject/.venv/lib/python3.10/site-packages/telegram/ext/dispatcher.py\", line 555, in process_update\n",
      "    handler.handle_update(update, self, check, context)\n",
      "  File \"/Users/liting/Desktop/7940_GroupProject/.venv/lib/python3.10/site-packages/telegram/ext/conversationhandler.py\", line 626, in handle_update\n",
      "    new_state = handler.handle_update(update, dispatcher, check_result, context)\n",
      "  File \"/Users/liting/Desktop/7940_GroupProject/.venv/lib/python3.10/site-packages/telegram/ext/handler.py\", line 198, in handle_update\n",
      "    return self.callback(update, context)\n",
      "  File \"/var/folders/j5/js2vmjfs7yb6qmgq9zlzmtjh0000gn/T/ipykernel_19291/1811651559.py\", line 41, in save_interests\n",
      "    user_ref.set({'interests': interests})\n",
      "  File \"/Users/liting/Desktop/7940_GroupProject/.venv/lib/python3.10/site-packages/google/cloud/firestore_v1/document.py\", line 167, in set\n",
      "    write_results = batch.commit(**kwargs)\n",
      "  File \"/Users/liting/Desktop/7940_GroupProject/.venv/lib/python3.10/site-packages/google/cloud/firestore_v1/batch.py\", line 61, in commit\n",
      "    commit_response = self._client._firestore_api.commit(\n",
      "  File \"/Users/liting/Desktop/7940_GroupProject/.venv/lib/python3.10/site-packages/google/cloud/firestore_v1/services/firestore/client.py\", line 1418, in commit\n",
      "    response = rpc(\n",
      "  File \"/Users/liting/Desktop/7940_GroupProject/.venv/lib/python3.10/site-packages/google/api_core/gapic_v1/method.py\", line 131, in __call__\n",
      "    return wrapped_func(*args, **kwargs)\n",
      "  File \"/Users/liting/Desktop/7940_GroupProject/.venv/lib/python3.10/site-packages/google/api_core/retry/retry_unary.py\", line 293, in retry_wrapped_func\n",
      "    return retry_target(\n",
      "  File \"/Users/liting/Desktop/7940_GroupProject/.venv/lib/python3.10/site-packages/google/api_core/retry/retry_unary.py\", line 153, in retry_target\n",
      "    _retry_error_helper(\n",
      "  File \"/Users/liting/Desktop/7940_GroupProject/.venv/lib/python3.10/site-packages/google/api_core/retry/retry_base.py\", line 221, in _retry_error_helper\n",
      "    raise final_exc from source_exc\n",
      "google.api_core.exceptions.RetryError: Timeout of 60.0s exceeded, last exception: 503 Getting metadata from plugin failed with error: ('invalid_grant: Invalid JWT Signature.', {'error': 'invalid_grant', 'error_description': 'Invalid JWT Signature.'})\n"
     ]
    }
   ],
   "source": [
    "# Defining state constants\n",
    "REGISTER, INTERESTS = range(2)\n",
    "\n",
    "# Initialize Firebase\n",
    "cred = credentials.Certificate(\"chatbot-13193-firebase-adminsdk-fbsvc-e36b24e648.json\")\n",
    "\n",
    "# Check if the Firebase app has been initialized\n",
    "if not firebase_admin._apps:\n",
    "    firebase_admin.initialize_app(cred)\n",
    "db = firestore.client()\n",
    "\n",
    "def start(update: Update, context: CallbackContext):\n",
    "    \"\"\"Start command, welcome the user and guide registration interest\"\"\"\n",
    "    update.message.reply_text(\n",
    "    \"Welcome to the interest matching chatbot!\\n\"\n",
    "    \"You can register your interests with the /register command, including:\\n\"\n",
    "    \"- Online games\\n\"\n",
    "    \"- VR experiences\\n\"\n",
    "    \"- Social media groups\\n\"\n",
    "    \"- Music\\n\"\n",
    "    \"- Dancing\\n\"\n",
    "    \"Then I'll help you find people with similar interests!\"\n",
    "    )\n",
    "\n",
    "def register(update: Update, context: CallbackContext):\n",
    "    \"\"\"Register Interests\"\"\"\n",
    "    update.message.reply_text(\n",
    "        \"Please tell me your areas of interest (separate with commas):\\n\"\n",
    "        \"Example: online gaming, social media, VR, sports, music, etc.\"\n",
    "    )\n",
    "    return INTERESTS\n",
    "\n",
    "def save_interests(update: Update, context: CallbackContext):\n",
    "    \"\"\"Saving user interests to Firestore\"\"\"\n",
    "    user_id = update.effective_user.id\n",
    "    interests = update.message.text.split(\",\")\n",
    "    interests = [interest.strip() for interest in interests]\n",
    "    \n",
    "    # Storing user interests in Firestore\n",
    "    user_ref = db.collection('users').document(str(user_id))\n",
    "    user_ref.set({'interests': interests})\n",
    "    \n",
    "    update.message.reply_text(\"Your interest has been registered successfully!You can find people with same interests as you by using /find_matches command\")\n",
    "    return ConversationHandler.END\n",
    "\n",
    "def find_matches(update: Update, context: CallbackContext):\n",
    "    \"\"\"Find matching users from Firestore\"\"\"\n",
    "    user_id = update.effective_user.id\n",
    "    user_ref = db.collection('users').document(str(user_id))\n",
    "    user_doc = user_ref.get()\n",
    "    if not user_doc.exists:\n",
    "        update.message.reply_text(\"You haven't registered your interest yet, please register first using the /register command!\")\n",
    "        return\n",
    "\n",
    "    user_interests = user_doc.to_dict()['interests']\n",
    "    user_interests = [interest.lower() for interest in user_interests]  \n",
    "    user_username = user_doc.to_dict().get('username', '未知用户')  \n",
    "\n",
    "    matches = []\n",
    "    users_ref = db.collection('users')\n",
    "    for doc in users_ref.stream():\n",
    "        other_user_id = doc.id\n",
    "        if other_user_id != str(user_id):\n",
    "            other_interests = doc.to_dict().get('interests', [])\n",
    "            other_interests = [interest.lower() for interest in other_interests]  \n",
    "            other_username = doc.to_dict().get('username', '未知用户')  \n",
    "\n",
    "            common_interests = set(user_interests) & set(other_interests)\n",
    "            if common_interests:\n",
    "                matches.append((other_user_id, other_username, common_interests))\n",
    "\n",
    "    if matches:\n",
    "        response = \"Here are users who share the same interests with you:\\n\"\n",
    "        for match in matches:\n",
    "            response += f\"User_Name: {match[1]}, User_ID: {match[0]}, Same_Interests: {', '.join(match[2])}\\n\"\n",
    "    else:\n",
    "        response = \"Sorry, we currently cannot find users who share your interests.\"\n",
    "    update.message.reply_text(response)\n",
    "\n",
    "\n",
    "def equiped_chatgpt(update,context):\n",
    "    global chatgpt\n",
    "    user_message = update.message.text\n",
    "    if \"match users with similar interests\" in user_message:\n",
    "        reply_message = \"OK, Please input /start command to start matching。\"\n",
    "    else:\n",
    "        reply_message = chatgpt.submit(user_message)\n",
    "    logging.info(\"Update: \"+str(update))\n",
    "    logging.info(\"context: \"+str(update))\n",
    "    context.bot.send_message(chat_id=update.effective_chat.id, text=reply_message)\n",
    "\n",
    "def main():\n",
    "    global chatgpt\n",
    "    # Load your token and create an Updater for your Bot\n",
    "    config = configparser.ConfigParser()\n",
    "    config.read('config.ini')\n",
    "    updater = Updater(token=(config['TELEGRAM']['ACCESS_TOKEN']), use_context=True)\n",
    "    dispatcher = updater.dispatcher\n",
    "    \n",
    "    # Initialize ChatGPT\n",
    "    chatgpt = HKBU_ChatGPT(config)\n",
    "\n",
    "    # Registering a Command Processor\n",
    "    start_handler = CommandHandler('start', start)\n",
    "    register_handler = ConversationHandler(\n",
    "        entry_points=[CommandHandler('register', register)],\n",
    "        states={\n",
    "            INTERESTS: [MessageHandler(Filters.text & (~Filters.command), save_interests)]\n",
    "        },\n",
    "        fallbacks=[]\n",
    "    )\n",
    "    find_matches_handler = CommandHandler('find_matches', find_matches)\n",
    "\n",
    "    dispatcher.add_handler(start_handler)\n",
    "    dispatcher.add_handler(register_handler)\n",
    "    dispatcher.add_handler(find_matches_handler)\n",
    "\n",
    "    chatgpt_handler = MessageHandler(Filters.text & (~Filters.command), equiped_chatgpt)\n",
    "    dispatcher.add_handler(chatgpt_handler)\n",
    "    \n",
    "    # To start the bot:\n",
    "    updater.start_polling()\n",
    "    updater.idle()\n",
    "\n",
    "if __name__ == '__main__':\n",
    "    main()"
   ]
  }
 ],
 "metadata": {
  "kernelspec": {
   "display_name": ".venv",
   "language": "python",
   "name": "python3"
  },
  "language_info": {
   "codemirror_mode": {
    "name": "ipython",
    "version": 3
   },
   "file_extension": ".py",
   "mimetype": "text/x-python",
   "name": "python",
   "nbconvert_exporter": "python",
   "pygments_lexer": "ipython3",
   "version": "3.10.16"
  }
 },
 "nbformat": 4,
 "nbformat_minor": 2
}
